Workbook

Sheet Executive_Summary
A1: MOE SINGAPORE EDUSAVE E-SERVICE PORTAL
A2: BỘ MA TRẬN TEST CASE TOÀN DIỆN PHÂN HỆ FS08 / R8
A3: Quy chuẩn kiểm thử: /combo-qa | ISO/IEC/IEEE 29119-3 Compliant | Ngày cập nhật: 21/10/2026
A5: Tổng Số Test Cases | B5: P0 (Blocker / Critical) | C5: P1 (High / Core) | D5: P2 (Medium / Normal) | E5: Đã Tự Động Hóa (Pytest) | F5: Sẵn Sàng Automation
A6: =COUNTA(Automation_Test_Matrix!A2:A500) | B6: =COUNTIF(Automation_Test_Matrix!G2:G500, "*Critical*") + COUNTIF(Automation_Test_Matrix!G2:G500, "P0") | C6: =COUNTIF(Automation_Test_Matrix!G2:G500, "*High*") + COUNTIF(Automation_Test_Matrix!G2:G500, "P1") | D6: =COUNTIF(Automation_Test_Matrix!G2:G500, "*Medium*") + COUNTIF(Automation_Test_Matrix!G2:G500, "P2") | E6: =COUNTIF(Automation_Test_Matrix!P2:P500, "Automated") | F6: =COUNTIF(Automation_Test_Matrix!P2:P500, "Automation Candidate")
A9: 1. PHÂN BỔ THEO TEST SUITE (13 PHÂN NHÓM + BREAK-IT)
A10: Mã Suite | B10: Tên Phân Nhóm Kiểm Thử | C10: Phạm Vi Nghiệp Vụ | D10: Số Lượng TC | E10: Độ Ưu Tiên | F10: Trạng Thái Automation
A11: TS-001 | B11: SingPass Login & MockPass Auth | C11: Đăng nhập SingPass, tạo mới hồ sơ, tái sử dụng tài khoản, timeout 10s (D-31) | D11: =COUNTIF(Automation_Test_Matrix!B2:B500, "TS-001") | E11: P0 / P1 | F11: Automated (5 TC) / Candidate
A12: TS-002 | B12: Login Data Refresh & On-Demand Sync | C12: Bảo lưu SĐT/Email đã sửa (AC #22), đồng bộ con, bỏ nightly sync (D-31) | D12: =COUNTIF(Automation_Test_Matrix!B2:B500, "TS-002") | E12: P0 / P1 | F12: Automated (1 TC) / Candidate
A13: TS-003 | B13: Session Lifecycle & Idle Timeout | C13: Hết hạn phiên sau 15 phút idle (D-22), nút logout, bảo vệ token | D13: =COUNTIF(Automation_Test_Matrix!B2:B500, "TS-003") | E13: P0 / P1 | F13: Automated (2 TC) / Candidate
A14: TS-004 | B14: Home Portal & Child Cards | C14: Thuật toán sắp xếp thẻ con 3 tầng (AC #12), xem trước 3 khoản phí, nhãn FAS | D14: =COUNTIF(Automation_Test_Matrix!B2:B500, "TS-004") | E14: P0 / P1 | F14: Automated (3 TC) / Candidate
A15: TS-005 | B15: Education Account Info Block | C15: 6 trạng thái EA, định dạng mã EA, xử lý năm nhuận 29/02 | D15: =COUNTIF(Automation_Test_Matrix!B2:B500, "TS-005") | E15: P0 / P1 | F15: Automated (3 TC) / Candidate
A16: TS-006 | B16: Education Account - Balance | C16: Khung vàng Pending tách biệt (AC #25), tổng dòng tiền Money in/out | D16: =COUNTIF(Automation_Test_Matrix!B2:B500, "TS-006") | E16: P0 / P1 | F16: Candidate (Ready)
A17: TS-007 | B17: Education Account - FAS Block | C17: Khối xanh FAS Granted (AC #27), nhãn Under review, ẩn khi không có trợ cấp | D17: =COUNTIF(Automation_Test_Matrix!B2:B500, "TS-007") | E17: P1 / P2 | F17: Candidate (Ready)
A18: TS-008 | B18: Education Account - Transactions Ledger | C18: Phân trang 20 dòng, bộ lọc loại/dòng tiền/ngày, export PDF statement | D18: =COUNTIF(Automation_Test_Matrix!B2:B500, "TS-008") | E18: P0 / P1 | F18: Automated (2 TC) / Candidate
A19: TS-009 | B19: Age 16 View-only Governance Rules | C19: Con 16 tuổi chuyển read-only; tính độc lập giữa các anh chị em (AC #7) | D19: =COUNTIF(Automation_Test_Matrix!B2:B500, "TS-009") | E19: P0 / P1 | F19: Automated (2 TC) / Candidate
A20: TS-010 | B20: My Details - Profile Management | C20: BVA Phone (6/8/9), Email (150 chars), Mailing, Read-only SingPass, Dirty/Cancel | D20: =COUNTIF(Automation_Test_Matrix!B2:B500, "TS-010") | E20: P0 / P1 / P2 | F20: Automated (14 TC) / Candidate
A21: TS-011 | B21: Authorization & Data Protection | C21: Chống IDOR xem con người khác (MSG-0003), che NRIC trên URL, không lộ PII | D21: =COUNTIF(Automation_Test_Matrix!B2:B500, "TS-011") | E21: P0 | F21: Automated (2 TC) / Candidate
A22: TS-012 | B22: Audit Log & Compliance Tracking | C22: Ghi log đăng nhập, log refresh data, log sửa My Details (old/new value) | D22: =COUNTIF(Automation_Test_Matrix!B2:B500, "TS-012") | E22: P1 | F22: Candidate (Ready)
A23: TS-013 | B23: Non-Functional Requirements (NFR) | C23: Hiệu năng Home/EA < 3s, Responsive mobile 390px, tiền tệ SGD, ngày Singapore | D23: =COUNTIF(Automation_Test_Matrix!B2:B500, "TS-013") | E23: P2 | F23: Candidate (Ready)
A24: TS-BRK | B24: Adversarial 'Break-It' & Chaos | C24: Gỡ validate client, XSS 3 vectors, Double-click debounce, Server 500, Focus trap | D24: =COUNTIF(Automation_Test_Matrix!B2:B500, "TS-BRK") | E24: P0 / P1 | F24: Automated 100% (8 TC)
A25: TỔNG CỘNG | D25: =SUM(D11:D24) | E25: Tất cả các Suite | F25: Tất cả các Suite

Sheet Automation_Test_Matrix
A1: Test Case ID | B1: Suite ID | C1: Suite Name | D1: Test Scenario / Title | E1: Page / Component | F1: Severity | G1: Priority | H1: Test Type | I1: Traceability (AC / FSD) | J1: Decision Ref | K1: Defect Ref | L1: Preconditions | M1: Deterministic Test Steps | N1: Concrete Test Data | O1: Expected Result (Exact Observable Assertion) | P1: Automation Status | Q1: Automated Function / Test File
A2: TC-R8-001 | B2: TS-001 | C2: SingPass Login | D2: Verify Landing page shows the 'Log in with SingPass' button | E2: Landing page | F2: S3 | G2: Medium | H2: UI | I2: FR-08.1; FS R8 sec. 6; US-08.1; PB-06 | L2: User is not logged in | M2: 1. Open the e-Service Portal URL 2. Observe the Landing page | N2: N/A | O2: Landing page is shown with the 'Log in with SingPass' button; no child or account data is shown | P2: Automated | Q2: tests/fs08/test_ts01_auth_and_session.py::test_tc_r8_001_landing_page_shows_singpass_button
A3: TC-R8-002 | B3: TS-001 | C3: SingPass Login | D3: Verify first-time SingPass login creates a parent account and opens Home | E3: Landing page > Home | F3: S1 (highest) | G3: Critical | H3: Functional | I3: FR-08.1 steps 1-5; R8-AC01; US-08.1; PB-06; PB-07 | L3: Father FA has never logged in (no Parent_Profile row for S7000001A) Data API returns FA and children A1, A2 | M3: 1. Open the Landing page 2. Click [Log in with SingPass] 3. Authenticate as FA in mock SingPass 4. Observe the page after redirect 5. Check Parent_Profile for NRIC S7000001A | N3: Father FA: NRIC S7000001A, Tan Wei Ming Mother MA: NRIC S7000002B, Lim Mei Ling Child A1: Tan Jia Hui, citizen, age 12, EA Active, balance S$250.00, BVP / P6 Integrity Child A2: Tan Jun Kai, citizen, age 9, EA Active, balance S$80.00, BVP / P3 Harmony | O3: Home is shown with one card for A1 and one card for A2 One Parent_Profile row exists with a UserId and IsActivate = true A1 and A2 are linked to FA Parent and child data are stored from the data API | P3: Automated | Q3: tests/fs08/test_ts01_auth_and_session.py::test_tc_r8_002_first_time_singpass_login_creates_parent_account_and_opens_home
A4: TC-R8-003 | B4: TS-001 | C4: SingPass Login | D4: Verify a returning parent reuses the existing account | E4: Landing page > Home | F4: S2 | G4: High | H4: Functional | I4: FR-08.1 step 3; R8-AC02; PB-06 | L4: FA has logged in before (Parent_Profile exists, UserId recorded) | M4: 1. Note FA's UserId and the Parent_Profile row count for S7000001A 2. Log out 3. Log in again via SingPass as FA 4. Re-check Parent_Profile | N4: Father FA: NRIC S7000001A, Tan Wei Ming Mother MA: NRIC S7000002B, Lim Mei Ling Child A1: Tan Jia Hui, citizen, age 12, EA Active, balance S$250.00, BVP / P6 Integrity Child A2: Tan Jun Kai, citizen, age 9, EA Active, balance S$80.00, BVP / P3 Harmony | O4: Login succeeds and Home is shown Same UserId; still exactly one Parent_Profile row for S7000001A; no duplicate child links | P4: Automated | Q4: tests/fs08/test_ts01_auth_and_session.py::test_tc_r8_003_returning_parent_reuses_existing_account
A5: TC-R8-004 | B5: TS-001 | C5: SingPass Login | D5: Verify cancelling SingPass returns to Landing with MSG-0802 | E5: Landing page | F5: S3 | G5: Medium | H5: Functional | I5: FR-08.1 errors; R8-AC05; PB-06 | L5: User is not logged in | M5: 1. Click [Log in with SingPass] 2. Click [Cancel] on the mock SingPass page | N5: Any mock SingPass identity | O5: User is returned to the Landing page MSG-0802 'Login was not completed. Try again.' is shown No session is created | P5: Automated | Q5: tests/fs08/test_ts01_auth_and_session.py::test_tc_r8_004_and_005_singpass_error_or_cancel_returns_msg0802
A6: TC-R8-005 | B6: TS-001 | C6: SingPass Login | D6: Verify a SingPass authentication error returns to Landing with MSG-0802 | E6: Landing page | F6: S2 | G6: High | H6: Integration | I6: FR-08.1 errors; R8-AC05; PB-06 | L6: Mock SingPass configured to return an error on callback | M6: 1. Click [Log in with SingPass] 2. Complete login on mock SingPass (mock returns an error) | N6: Mock SingPass error response | O6: User is returned to the Landing page with MSG-0802 No session; no Parent_Profile created or changed | P6: Automated | Q6: tests/fs08/test_ts01_auth_and_session.py::test_tc_r8_004_and_005_singpass_error_or_cancel_returns_msg0802
A7: TC-R8-006 | B7: TS-001 | C7: SingPass Login | D7: Verify login is refused when the NRIC is not found in the data API | E7: Landing page | F7: S2 | G7: High | H7: Functional | I7: FR-08.1 rules; R8-AC03; PB-07 | L7: NRIC S7999999Z exists in mock SingPass but not in the data API | M7: 1. Click [Log in with SingPass] 2. Authenticate as S7999999Z 3. Check Parent_Profile | N7: NRIC: S7999999Z | O7: MSG-0801 'We could not find any student linked to your account. Please contact your child's school.' is shown User cannot enter the portal; no Parent_Profile row created | P7: Automated | Q7: tests/fs08/test_ts02_accounts_and_transactions.py::test_tc_r8_006_under_age_7_or_uninitialized_ea_msg0804
A8: TC-R8-007 | B8: TS-001 | C8: SingPass Login | D8: Verify login is refused when the parent has no linked child | E8: Landing page | F8: S2 | G8: High | H8: Functional | I8: FR-08.1 rules; R8-AC03; PB-07 | L8: Parent S7000009H exists in the data API; no student has this NRIC as FatherNric/MotherNric | M8: 1. Log in via SingPass as S7000009H | N8: NRIC: S7000009H | O8: MSG-0801 is shown User cannot enter the portal; no session is created | P8: Automated | Q8: tests/fs08/test_ts01_auth_and_session.py::test_tc_r8_007_login_refused_no_linked_child_msg0801
A9: TC-R8-008 | B9: TS-001 | C9: SingPass Login | D9: Verify login is refused when the data API returns an error | E9: Landing page | F9: S2 | G9: High | H9: Integration | I9: FR-08.1 errors; R8-AC23 | L9: FA has logged in before; mock data API configured to return HTTP 500 | M9: 1. Note FA's Parent_Profile and A1/A2 data 2. Log in via SingPass as FA 3. Re-check the data | N9: Father FA: NRIC S7000001A, Tan Wei Ming Mother MA: NRIC S7000002B, Lim Mei Ling Child A1: Tan Jia Hui, citizen, age 12, EA Active, balance S$250.00, BVP / P6 Integrity Child A2: Tan Jun Kai, citizen, age 9, EA Active, balance S$80.00, BVP / P3 Harmony | O9: MSG-0809 'We could not retrieve your information. Please try again later.' is shown User cannot enter the portal Parent and child data are unchanged | P9: Automation Candidate | Q9: Planned
A10: TC-R8-009 | B10: TS-001 | C10: SingPass Login | D10: Verify login is refused when the data API takes longer than 10 seconds | E10: Landing page | F10: S2 | G10: High | H10: Integration | I10: FR-08.1 errors; NFR Integration (10 s timeout); R8-AC23 | L10: Mock data API configured to respond after 11 seconds | M10: 1. Log in via SingPass as FA 2. Measure time until a message is shown | N10: Father FA: NRIC S7000001A, Tan Wei Ming Mother MA: NRIC S7000002B, Lim Mei Ling Child A1: Tan Jia Hui, citizen, age 12, EA Active, balance S$250.00, BVP / P6 Integrity Child A2: Tan Jun Kai, citizen, age 9, EA Active, balance S$80.00, BVP / P3 Harmony API delay: 11 s | O10: Request times out at about 10 seconds MSG-0809 is shown; user cannot enter; data unchanged | P10: Automation Candidate | Q10: Planned
A11: TC-R8-010 | B11: TS-001 | C11: SingPass Login | D11: Verify login succeeds when the data API responds just under 10 seconds | E11: Landing page > Home | F11: S3 | G11: Medium | H11: Integration | I11: NFR Integration (10 s timeout) - boundary | L11: Mock data API configured to respond after 9 seconds | M11: 1. Log in via SingPass as FA | N11: Father FA: NRIC S7000001A, Tan Wei Ming Mother MA: NRIC S7000002B, Lim Mei Ling Child A1: Tan Jia Hui, citizen, age 12, EA Active, balance S$250.00, BVP / P6 Integrity Child A2: Tan Jun Kai, citizen, age 9, EA Active, balance S$80.00, BVP / P3 Harmony API delay: 9 s | O11: Login completes and Home is shown; no MSG-0809 | P11: Automated | Q11: tests/fs08/test_ts02_accounts_and_transactions.py::test_tc_r8_010_non_singapore_citizen_ea_hidden_and_notice
A12: TC-R8-011 | B12: TS-001 | C12: SingPass Login | D12: Verify login is refused when saving the refreshed data fails | E12: Landing page | F12: S2 | G12: High | H12: Integration | I12: FR-08.1 rules ('Cập nhật lỗi: MSG-0809') | L12: FA has logged in before; DB write for the login data update is forced to fail (fault injection) | M12: 1. Note FA's Parent_Profile and A1/A2 data 2. Log in via SingPass as FA 3. Re-check the data | N12: Father FA: NRIC S7000001A, Tan Wei Ming Mother MA: NRIC S7000002B, Lim Mei Ling Child A1: Tan Jia Hui, citizen, age 12, EA Active, balance S$250.00, BVP / P6 Integrity Child A2: Tan Jun Kai, citizen, age 9, EA Active, balance S$80.00, BVP / P3 Harmony | O12: MSG-0809 is shown; user cannot enter the portal No partial update: parent and child data are unchanged | P12: Automation Candidate | Q12: Planned
A13: TC-R8-012 | B13: TS-001 | C13: SingPass Login | D13: Verify father and mother both see the same children with the same rights | E13: Home | F13: S2 | G13: High | H13: Functional | I13: FR-08.1 rules (D-19); R8-AC04; PB-07 | L13: A1 and A2 have FatherNric = S7000001A and MotherNric = S7000002B | M13: 1. Log in as FA and note the cards and actions on Home and EA screens 2. Log out 3. Log in as MA and compare | N13: Father FA: NRIC S7000001A, Tan Wei Ming Mother MA: NRIC S7000002B, Lim Mei Ling Child A1: Tan Jia Hui, citizen, age 12, EA Active, balance S$250.00, BVP / P6 Integrity Child A2: Tan Jun Kai, citizen, age 9, EA Active, balance S$80.00, BVP / P3 Harmony | O13: FA and MA both see A1 and A2 with the same data and the same available actions | P13: Automated | Q13: tests/fs08/test_ts01_auth_and_session.py::test_tc_r8_012_dual_parent_equality_d19
... A16: TC-R8-015 | B16: TS-001 | C16: SingPass Login | D16: Verify an MOE HQ or School user without children cannot use the e-Service Portal | E16: Landing page | F16: S3 | G16: Low | H16: Security | I16: Sec. 4 permissions | L16: HQ user identity S7000010K has no linked child in the data API | M16: 1. Log in via SingPass as S7000010K | N16: NRIC: S7000010K | O16: MSG-0801 is shown; no access to the e-Service Portal | P16: Automation Candidate | Q16: Planned
A17: TC-R8-016 | B17: TS-001 | C17: SingPass Login | D17: Verify a protected page cannot be opened without logging in | E17: Home / Education Account | F17: S1 (highest) | G17: Critical | H17: Security | I17: NFR Security; PB-06 AC (unauthenticated access blocked) | J17: ASM-17: Unauthenticated access to a protected page redirects to the Landing page; protected APIs return 401. | L17: No active session | M17: 1. In a new private window, open the Home URL directly 2. Repeat for the Education Account and My details URLs | N17: URLs of Home, Education Account and My details | O17: Each request redirects to the Landing page; no parent or child data is shown | P17: Automation Candidate | Q17: Planned
A18: TC-R8-017 | B18: TS-001 | C18: SingPass Login | D18: Verify protected APIs reject calls without a valid session | E18: API | F18: S1 (highest) | G18: Critical | H18: API | I18: NFR Security; PB-06 | J18: ASM-17: Unauthenticated access to a protected page redirects to the Landing page; protected APIs return 401. | L18: No session token | M18: 1. Call each endpoint without a token 2. Call each endpoint with an expired or tampered token | N18: Endpoints: parent profile, children list, EA details, transactions | O18: Every call returns 401 with no data in the response body | P18: Automated | Q18: tests/fs08/test_ts03_parent_profile.py::test_tc_r8_017_profile_update_system_error_msg0808
A19: TC-R8-018 | B19: TS-002 | C19: Login Data Refresh | D19: Verify parent name and residential address are refreshed from SingPass at login | E19: My details | F19: S2 | G19: High | H19: Functional | I19: FR-08.1 rules (parent update); FS R8 Appendix A | L19: FA has logged in before; mock SingPass now returns a new residential address | M19: 1. Log in as FA 2. Open My details | N19: Old: Blk 214 Bukit Verde Ave 4, #08-102, 650214 New: Blk 88 Marina Crest Rd, #03-15, 440088 | O19: Residential address shows the new value; full name matches SingPass Audit log records the update | P19: Automation Candidate | Q19: Planned
A20: TC-R8-019 | B20: TS-002 | C20: Login Data Refresh | D20: Verify phone, email and mailing address are filled from the data API on first login | E20: My details | F20: S2 | G20: High | H20: Functional | I20: FR-08.1 rules | J20: ASM-02: Phone, email and mailing address are taken from the data API only on first login; later logins never overwrite them (edited or not). FS R8 wording is ambiguous for values the parent never edited; confirm with BA. | L20: FA has never logged in; data API returns phone, email and mailing address | M20: 1. Log in as FA for the first time 2. Open My details | N20: Phone 91234567; email weiming.tan@example.sg; mailing Blk 214 Bukit Verde Ave 4, #08-102, 650214, Singapore | O20: Phone, email and mailing address show the values from the data API | P20: Automation Candidate | Q20: Planned
A21: TC-R8-020 | B21: TS-002 | C21: Login Data Refresh | D21: Verify a phone number edited in My details is not overwritten at the next login | E21: My details | F21: S2 | G21: High | H21: Functional | I21: FR-08.1 rules; R8-AC22 | L21: FA changed phone to 98887777 in My details; data API still returns 91234567 | M21: 1. Log out 2. Log in again as FA 3. Open My details | N21: Edited phone: 98887777 API phone: 91234567 | O21: Phone is still 98887777 | P21: Automated | Q21: tests/fs08/test_ts01_auth_and_session.py::test_tc_r8_020_session_inactivity_timeout_msg0002
A22: TC-R8-021 | B22: TS-002 | C22: Login Data Refresh | D22: Verify edited email and mailing address are not overwritten at the next login | E22: My details | F22: S2 | G22: High | H22: Functional | I22: FR-08.1 rules; R8-AC22 | L22: FA edited email and mailing street in My details; data API returns different values | M22: 1. Log out 2. Log in again as FA 3. Open My details | N22: Edited email: fa.new@example.sg; edited street: 9 Verde Walk API values: weiming.tan@example.sg; Bukit Verde Ave 4 | O22: Email and mailing address keep the edited values | P22: Automation Candidate | Q22: Planned
A23: TC-R8-022 | B23: TS-002 | C23: Login Data Refresh | D23: Verify contact fields never edited by the parent are not refreshed after first login | E23: My details | F23: S3 | G23: Medium | H23: Functional | I23: FR-08.1 rules | J23: ASM-02: Phone, email and mailing address are taken from the data API only on first login; later logins never overwrite them (edited or not). FS R8 wording is ambiguous for values the parent never edited; confirm with BA. | L23: FA has logged in before and never edited email; data API now returns a different email | M23: 1. Log in as FA 2. Open My details | N23: Stored email: weiming.tan@example.sg New API email: wm.tan@example.sg | O23: Email remains weiming.tan@example.sg | P23: Automation Candidate | Q23: Planned
A24: TC-R8-023 | B24: TS-002 | C24: Login Data Refresh | D24: Verify a change to a child's class in the data API appears after the parent logs in | E24: Home | F24: S2 | G24: High | H24: Functional | I24: FR-08.1 rules (child update); R8-AC21 | J24: ASM-01: FS R8 FR-08.1 refreshes child name, school, class, DOB, citizenship at each login. FS R1 v1.2 (sec. 3) says R8 only verifies the parent-student relationship and does not run a full student sync; the Government dataset has no school/class. Test follows FS R8; confirm with BA. | L24: A1 class changed from P6 Integrity to P6 Harmony in the data API | M24: 1. Log in as FA 2. View A1's card on Home and A1's Education Account | N24: Father FA: NRIC S7000001A, Tan Wei Ming Mother MA: NRIC S7000002B, Lim Mei Ling Child A1: Tan Jia Hui, citizen, age 12, EA Active, balance S$250.00, BVP / P6 Integrity Child A2: Tan Jun Kai, citizen, age 9, EA Active, balance S$80.00, BVP / P3 Harmony | O24: A1 shows class P6 Harmony on Home and on the Education Account screen | P24: Automated | Q24: tests/fs08/test_ts01_auth_and_session.py::test_tc_r8_023_api_timeout_or_error_returns_msg0809
A25: TC-R8-024 | B25: TS-002 | C25: Login Data Refresh | D25: Verify child name, DOB and citizenship are refreshed at login | E25: Education Account | F25: S2 | G25: High | H25: Functional | I25: FR-08.1 rules (child update) | J25: ASM-01: FS R8 FR-08.1 refreshes child name, school, class, DOB, citizenship at each login. FS R1 v1.2 (sec. 3) says R8 only verifies the parent-student relationship and does not run a full student sync; the Government dataset has no school/class. Test follows FS R8; confirm with BA. | L25: Data API has a new full name for A2 | M25: 1. Log in as FA 2. Open A2's Education Account | N25: A2 new name: Tan Jun Kai Marcus | O25: Student information shows the new name; DOB and citizenship match the data API Audit log records the update | P25: Automation Candidate | Q25: Planned
A26: TC-R8-025 | B26: TS-002 | C26: Login Data Refresh | D26: Verify a child no longer linked to the parent's NRIC is unlinked at login | E26: Home | F26: S1 (highest) | G26: Critical | H26: Security | I26: FR-08.1 rules (unlink); NFR Security; PB-07 | L26: A2's FatherNric changed in the data API to a different NRIC | M26: 1. Note A2's EA URL while logged in as FA 2. Log out, apply the API change, log in as FA 3. View Home 4. Open the saved A2 URL | N26: Father FA: NRIC S7000001A, Tan Wei Ming Mother MA: NRIC S7000002B, Lim Mei Ling Child A1: Tan Jia Hui, citizen, age 12, EA Active, balance S$250.00, BVP / P6 Integrity Child A2: Tan Jun Kai, citizen, age 9, EA Active, balance S$80.00, BVP / P3 Harmony | O26: A2's card is no longer on Home Opening A2's URL shows MSG-0003 'You do not have permission to perform this action.' and no data | P26: Automation Candidate | Q26: Planned
A27: TC-R8-026 | B27: TS-002 | C27: Login Data Refresh | D27: Verify a newly linked child appears at the next login | E27: Home | F27: S2 | G27: High | H27: Functional | I27: FR-08.1 rules | L27: New child A3 (age 7, citizen) added in the data API with FatherNric S7000001A | M27: 1. Log in as FA 2. View Home | N27: Father FA: NRIC S7000001A, Tan Wei Ming Mother MA: NRIC S7000002B, Lim Mei Ling Child A1: Tan Jia Hui, citizen, age 12, EA Active, balance S$250.00, BVP / P6 Integrity Child A2: Tan Jun Kai, citizen, age 9, EA Active, balance S$80.00, BVP / P3 Harmony Child A3: Tan Mei Xin, age 7 | O27: A3's card is shown in addition to A1 and A2 | P27: Automation Candidate | Q27: Planned
A28: TC-R8-027 | B28: TS-002 | C28: Login Data Refresh | D28: Verify there is no nightly refresh for a parent who does not log in | E28: Database | F28: S2 | G28: Medium | H28: Functional | I28: FR-08.1 rules; NFR Integration; R8-AC24 | L28: FA logged in on day D; on day D the data API changes A1's class and FA's name; FA does not log in | M28: 1. On day D+1, check A1 and FA data in the database (FA has not logged in) 2. Log in as FA 3. Check the data again | N28: Father FA: NRIC S7000001A, Tan Wei Ming Mother MA: NRIC S7000002B, Lim Mei Ling Child A1: Tan Jia Hui, citizen, age 12, EA Active, balance S$250.00, BVP / P6 Integrity Child A2: Tan Jun Kai, citizen, age 9, EA Active, balance S$80.00, BVP / P3 Harmony | O28: On D+1 before login the data is unchanged After FA logs in the data is updated | P28: Automation Candidate | Q28: Planned
A29: TC-R8-028 | B29: TS-002 | C29: Login Data Refresh | D29: Verify the refresh at login only updates the logged-in parent and their children | E29: Database | F29: S2 | G29: High | H29: Functional | I29: FR-08.1 rules | L29: Parent PB (S7000003C) with child B2 has newer data in the API; FA logs in | M29: 1. Change PB and B2 data in the API 2. Log in as FA 3. Check PB and B2 rows in the database | N29: Parent PB: NRIC S7000003C Child B2: age 14 | O29: PB and B2 rows are unchanged; only FA, A1 and A2 are refreshed | P29: Automation Candidate | Q29: Planned
A30: TC-R8-029 | B30: TS-002 | C30: Login Data Refresh | D30: Verify 'Last updated' shows the time of the latest login refresh | E30: Education Account | F30: S3 | G30: Medium | H30: Functional | I30: FR-08.2; FS R8 6.2 (Last updated) | J30: ASM-24: 'Last updated' = time of the latest login data update for this parent (FS R8 6.2). May change if ASM-01 is revised. | L30: FA logs in at a known time | M30: 1. Log in as FA at 14/10/2026 09:15 2. Open A1's Education Account 3. Read 'Last updated' | N30: Father FA: NRIC S7000001A, Tan Wei Ming Mother MA: NRIC S7000002B, Lim Mei Ling Child A1: Tan Jia Hui, citizen, age 12, EA Active, balance S$250.00, BVP / P6 Integrity Child A2: Tan Jun Kai, citizen, age 9, EA Active, balance S$80.00, BVP / P3 Harmony | O30: Last updated' shows 14/10/2026 09:15 (DD/MM/YYYY HH:mm, Singapore time) | P30: Automation Candidate | Q30: Planned
A31: TC-R8-030 | B31: TS-003 | C31: Session | D31: Verify the session ends after 15 minutes of inactivity | E31: Any page | F31: S2 | G31: High | H31: Security | I31: NFR session (D-22); R8-AC20 | L31: FA logged in on Home | M31: 1. Stay idle for 15 minutes 2. Click any link or button | N31: Father FA: NRIC S7000001A, Tan Wei Ming Mother MA: NRIC S7000002B, Lim Mei Ling Child A1: Tan Jia Hui, citizen, age 12, EA Active, balance S$250.00, BVP / P6 Integrity Child A2: Tan Jun Kai, citizen, age 9, EA Active, balance S$80.00, BVP / P3 Harmony | O31: User is logged out; MSG-0002 'Your session has expired. Please log in again.' is shown; Landing page is displayed | P31: Automated | Q31: tests/fs08/test_ts01_auth_and_session.py::test_tc_r8_030_logout_and_session_cleared
A32: TC-R8-031 | B32: TS-003 | C32: Session | D32: Verify the session stays active after 14 minutes of inactivity | E32: Any page | F32: S3 | G32: Medium | H32: Security | I32: NFR session (D-22) - boundary | L32: FA logged in on Home | M32: 1. Stay idle for 14 minutes 2. Open A1's Education Account | N32: Father FA: NRIC S7000001A, Tan Wei Ming Mother MA: NRIC S7000002B, Lim Mei Ling Child A1: Tan Jia Hui, citizen, age 12, EA Active, balance S$250.00, BVP / P6 Integrity Child A2: Tan Jun Kai, citizen, age 9, EA Active, balance S$80.00, BVP / P3 Harmony | O32: Page opens normally; no MSG-0002 | P32: Automation Candidate | Q32: Planned
A33: TC-R8-032 | B33: TS-003 | C33: Session | D33: Verify an expired session cannot save My details | E33: My details | F33: S2 | G33: High | H33: Functional | I33: FR-08.3 errors; NFR session | L33: FA on My details with an edited phone not yet saved | M33: 1. Edit phone to 98887777 2. Stay idle 15 minutes 3. Click [Save] | N33: Phone: 98887777 | O33: MSG-0002 is shown; user is sent to Landing page Phone in the database is unchanged | P33: Automation Candidate | Q33: Planned
A34: TC-R8-033 | B34: TS-003 | C34: Session | D34: Verify logout ends the session | E34: Any page | F34: S2 | G34: High | H34: Security | I34: FS R8 sec. 3 step 9; NFR Security | L34: FA logged in | M34: 1. Click [Log out] 2. Press the browser Back button 3. Re-use the old token on the EA API | N34: Father FA: NRIC S7000001A, Tan Wei Ming Mother MA: NRIC S7000002B, Lim Mei Ling Child A1: Tan Jia Hui, citizen, age 12, EA Active, balance S$250.00, BVP / P6 Integrity Child A2: Tan Jun Kai, citizen, age 9, EA Active, balance S$80.00, BVP / P3 Harmony | O34: Landing page is shown; Back does not show child data API call with the old token returns 401 | P34: Automation Candidate | Q34: Planned
A35: TC-R8-034 | B35: TS-004 | C35: Home | D35: Verify each linked child has a card with name, EA status, school and class | E35: Home | F35: S2 | G35: High | H35: UI | I35: FS R8 6.1; R8-AC01 | L35: FA logged in | M35: 1. Open Home 2. Check the header of each card | N35: Father FA: NRIC S7000001A, Tan Wei Ming Mother MA: NRIC S7000002B, Lim Mei Ling Child A1: Tan Jia Hui, citizen, age 12, EA Active, balance S$250.00, BVP / P6 Integrity Child A2: Tan Jun Kai, citizen, age 9, EA Active, balance S$80.00, BVP / P3 Harmony | O35: One card per child; each shows student name, EA status label, school and class | P35: Automated | Q35: tests/fs08/test_ts02_accounts_and_transactions.py::test_tc_r8_034_and_051_view_active_child_card_and_ea_balance
A36: TC-R8-035 | B36: TS-004 | C36: Home | D36: Verify the EA balance is shown on the card for an Active account | E36: Home | F36: S2 | G36: High | H36: Functional | I36: FS R8 6.1 (EA balance) | L36: A1 EA Active, balance S$250.00 | M36: 1. Open Home 2. Check A1's card | N36: Father FA: NRIC S7000001A, Tan Wei Ming Mother MA: NRIC S7000002B, Lim Mei Ling Child A1: Tan Jia Hui, citizen, age 12, EA Active, balance S$250.00, BVP / P6 Integrity Child A2: Tan Jun Kai, citizen, age 9, EA Active, balance S$80.00, BVP / P3 Harmony | O36: A1 card shows status Active and EA balance S$250.00 | P36: Automation Candidate | Q36: Planned
A37: TC-R8-036 | B37: TS-004 | C37: Home | D37: Verify the EA balance is shown on the card for a Due for closure account | E37: Home | F37: S3 | G37: Medium | H37: Functional | I37: FS R8 6.1; 6.2 | J37: ASM-03: Per FS R1 v1.2 F02, opening the EA of a child aged 16+ triggers the closure eligibility check. Balance = 0 -> account becomes Closed; 'Due for closure' is expected only when balance > 0 and CPF transfer is deferred. Confirm with BA. | L37: Child B1 is 16+, EA not closed, balance S$40.00 | M37: 1. Log in as PB 2. Check B1's card | N37: Parent PB: S7000003C Child B1: age 16, EA balance S$40.00 | O37: B1 card shows status Due for closure and EA balance S$40.00 | P37: Automation Candidate | Q37: Planned
A38: TC-R8-037 | B38: TS-004 | C38: Home | D38: Verify the balance is replaced by a status sentence for children without a usable EA | E38: Home | F38: S2 | G38: High | H38: Functional | I38: FS R8 6.1; 6.2; R8-AC10 | J38: ASM-07: Card position for Closed / To be created / Not yet 7 / Not eligible children is not defined in FS R8 sec. 6.1. Record the actual order and confirm with BA. | L38: Parent PC has children: C1 Closed EA, C2 citizen age 7 without EA, C3 citizen age 5, C4 non-citizen age 10 | M38: 1. Log in as PC 2. Check each card | N38: Parent PC: S7000004D C1 Closed; C2 To be created; C3 Not yet 7 (DOB 20/05/2021); C4 PR | O38: No balance is shown on any card C2: 'Education Account not active yet.' C3: sentence with opening date 20/05/2028 C4: 'Education Accounts are for Singapore Citizens' C1: Closed status, no balance | P38: Automated | Q38: tests/fs08/test_ts02_accounts_and_transactions.py::test_tc_r8_037_child_cards_three_tier_sorting_order
A39: TC-R8-038 | B39: TS-004 | C39: Home | D39: Verify 'Need to pay' shows total outstanding fees after subsidy | E39: Home | F39: S2 | G39: High | H39: Functional | I39: FS R8 6.1 (Need to pay) | J39: ASM-22: FAS (R4/R10) is not delivered in Sprint 1; FAS status is seeded as mock data.<br><br>ASM-23: Fee/charge data (R3/R9) is seeded as POSTED student charges with due dates. | L39: A1 has POSTED charges S$120.00 and S$80.00; FAS subsidy reduces S$80.00 to S$40.00 | M39: 1. Log in as FA 2. Check 'Need to pay' on A1's card | N39: A1 charges: Misc fee S$120.00; Textbooks S$80.00 (subsidy -S$40.00) | O39: Need to pay' shows S$160.00 | P39: Automation Candidate | Q39: Planned
A40: TC-R8-039 | B40: TS-004 | C40: Home | D40: Verify the FAS label appears only for a Granted FAS | E40: Home | F40: S3 | G40: Medium | H40: Functional | I40: FS R8 6.1 (FAS label) | J40: ASM-22: FAS (R4/R10) is not delivered in Sprint 1; FAS status is seeded as mock data. | L40: A1 has MOEFAS Tier 2 Granted; A2 has an FAS under review | M40: 1. Log in as FA 2. Check the cards of A1 and A2 | N40: Father FA: NRIC S7000001A, Tan Wei Ming Mother MA: NRIC S7000002B, Lim Mei Ling Child A1: Tan Jia Hui, citizen, age 12, EA Active, balance S$250.00, BVP / P6 Integrity Child A2: Tan Jun Kai, citizen, age 9, EA Active, balance S$80.00, BVP / P3 Harmony | O40: A1 card shows 'MOEFAS Tier 2' A2 card shows no FAS label | P40: Automation Candidate | Q40: Planned
A41: TC-R8-040 | B41: TS-004 | C41: Home | D41: Verify the card lists at most 3 outstanding fees sorted by nearest due date | E41: Home | F41: S3 | G41: Medium | H41: Functional | I41: FS R8 6.1 (fee list) - boundary 3 | J41: ASM-06: 'Due soon' threshold is not defined; assumed due date within the next 7 days. Overdue = due date before today; Not due yet = otherwise.<br><br>ASM-23: Fee/charge data (R3/R9) is seeded as POSTED student charges with due dates. | L41: A1 has 3 outstanding charges with different due dates | M41: 1. Log in as FA 2. Check the fee list on A1's card | N41: Due 20/10/2026 S$30.00; due 05/11/2026 S$45.00; due 10/10/2026 S$20.00 (overdue) | O41: 3 rows in this order: due 10/10, 20/10, 05/11 Each row shows fee name, status (Overdue / Due soon / Not due yet) and amount No '+N more' line | P41: Automation Candidate | Q41: Planned
A42: TC-R8-041 | B42: TS-004 | C42: Home | D42: Verify '+N more' appears when there are more than 3 outstanding fees | E42: Home | F42: S3 | G42: Medium | H42: Functional | I42: FS R8 6.1; R8-AC19 | J42: ASM-23: Fee/charge data (R3/R9) is seeded as POSTED student charges with due dates. | L42: A1 has 5 outstanding charges | M42: 1. Log in as FA 2. Check A1's card | N42: 5 POSTED charges with due dates 10/10, 20/10, 05/11, 30/11, 15/12/2026 | O42: The 3 nearest-due charges are shown, then '+2 more' | P42: Automation Candidate | Q42: Planned
...

Sheet Sprint_1_Defects
A1: Defect ID | B1: Defect Summary | C1: Severity | D1: Priority | E1: Status | F1: Linked Test Case | G1: Preconditions | H1: Steps to Reproduce | I1: Expected Result (FSD Standard) | J1: Actual Defect Behavior | K1: Automation Test Guard & Verification Method
A2: BUG-R8-001 | B2: [My details] No success message after saving valid phone, email and mailing address | C2: S2 | D2: High | E2: Open | F2: TC-R8-097 | G2: Family Account holder (FA) is logged in; on /profile Edit Mode | H2: 1. Open My details 2. Enter phone 98887777, email fa.new@example.sg, valid mailing 3. Click Save changes & confirm | I2: MSG-0807 'Your details have been updated.' is shown. Values persist after reload. Audit log recorded. No email sent (D-28). | J2: No success message displayed after profile updated. | K2: tests/fs08/test_ts03_parent_profile.py::test_tc_r8_097_profile_update_successful_with_confirm_dialog
A3: BUG-R8-002 | B3: [My details] Invalid mobile numbers (starting with 7, 5, or wrong length) are accepted and saved | C3: S2 | D3: High | E3: Open | F3: TC-R8-099 | G3: Family Account holder (FA) is logged in; on /profile Edit Mode | H3: 1. Open My details 2. Enter: 71234567, 51234567, 9123456, 912345678, +6591234567 3. Click Save changes | I3: MSG-0805 'Enter a mobile number in the correct format, like 9123 4567' is shown and nothing is saved. | J3: Invalid mobile numbers can be saved. MSG-0805 is not shown. | K3: tests/fs08/test_ts03_parent_profile.py::test_tc_r8_099_reject_invalid_singapore_mobile_number
A4: BUG-R8-003 | B4: [My details] Mobile number entered with a space is saved with the space instead of being trimmed | C4: S4 | D4: Low | E4: Open | F4: TC-R8-100 / TC-PROF-P09 | G4: Family Account holder (FA) is logged in; on /profile Edit Mode | H4: 1. Open My details 2. Enter mobile number '9123 4567' 3. Click Save 4. Check stored value | I4: Saved with MSG-0807 and stored as 91234567 (space trimmed) or formatted properly. | J4: Saved with the space kept verbatim in DB. | K4: tests/fs08/test_ts03_parent_profile.py::test_tc_prof_p09_mobile_number_with_space
A5: BUG-R8-004 | B5: [My details] Invalid email message does not match MSG-0806 (missing example 'like name@example.com') | C5: S4 | D5: Low | E5: Open | F5: TC-R8-101 | G5: Family Account holder (FA) is logged in; on /profile Edit Mode | H5: 1. Open My details 2. Enter invalid email (e.g. nameexample.com) 3. Click Save | I5: MSG-0806 verbatim: 'Enter an email address in the correct format, like name@example.com'. | J5: The message shown is 'Enter an email address in the correct format.' The example is missing. | K5: tests/fs08/test_ts03_parent_profile.py::test_tc_r8_101_reject_invalid_email_format_msg0806
A6: BUG-R8-005 | B6: [My details] Required fields cannot be cleared (revert on blur), so MSG-0001 cannot be triggered | C6: S2 | D6: High | E6: Open | F6: TC-R8-103 / TC-PROF-P13 | G6: Family Account holder (FA) is logged in; on /profile Edit Mode | H6: 1. Open My details 2. Clear Mobile number, Email, Mailing street, Postal code 3. Click Save | I6: MSG-0001 is shown under each blank field ('Enter your <field>') and submit is prevented. | J6: Required fields cannot be cleared or old value reverts on blur, so blank validation cannot be reached. | K6: tests/fs08/test_ts03_parent_profile.py::test_tc_prof_p13_required_fields_empty_validation_msg0001

Sheet Messages_&_Rules
A1: DANH MỤC THÔNG ĐIỆP HỆ THỐNG FS08 (TABLE 124 CATALOG)
A2: Mã Thông Điệp | B2: Chuỗi Ký Tự Tiếng Anh Verbatim (Exact String) | C2: Ngữ Cảnh Kích Hoạt | D2: Kịch Bản Kiểm Thử Xác Thực
A3: MSG-0801 | B3: We could not find any student linked to your account. Please contact your child's school. | C3: SingPass NRIC không có học sinh liên kết trong Mock Data API | D3: TC-R8-007
A4: MSG-0802 | B4: Login was not completed. Try again. | C4: SingPass Mock trả về mã lỗi hoặc người dùng chủ động bấm Hủy | D4: TC-R8-004, TC-R8-005
A5: MSG-0803 | B5: No transactions found. | C5: Áp dụng bộ lọc giao dịch nhưng không có kết quả khớp | D5: TC-R8-081
A6: MSG-0804 | B6: This student does not have an Education Account. | C6: Học sinh công dân đủ tuổi nhưng chưa có bản ghi tài khoản EA | D6: TC-R8-006
A7: MSG-0805 | B7: Enter a mobile number in the correct format, like 9123 4567 | C7: Nhập SĐT sai định dạng Singapore (không bắt đầu 6,8,9 hoặc sai độ dài) | D7: TC-R8-099, BUG-R8-002
A8: MSG-0806 | B8: Enter an email address in the correct format, like name@example.com | C8: Nhập email sai định dạng RFC hoặc vượt quá 150 ký tự | D8: TC-R8-101, BUG-R8-004
A9: MSG-0807 | B9: Your details have been updated. | C9: Lưu thông tin cá nhân My details thành công | D9: TC-R8-097, BUG-R8-001
A10: MSG-0808 | B10: We could not update your details. Please try again. | C10: Lỗi máy chủ HTTP 500 hoặc mất kết nối DB khi lưu profile | D10: TC-R8-017, TC-R8-BRK-006
A11: MSG-0809 | B11: We could not retrieve your information. Please try again later. | C11: Data API timeout quá 10 giây hoặc trả HTTP 500 lúc đăng nhập (D-31) | D11: TC-R8-023
A12: MSG-0001 | B12: Enter your <field> | C12: Bỏ trống trường bắt buộc trong My details (Mobile, Email, Street, Postal, Country) | D12: TC-PROF-P13, BUG-R8-005
A13: MSG-0002 | B13: Your session has expired. Please log in again. | C13: Hết hạn phiên làm việc do không thao tác trong 15 phút (D-22) | D13: TC-R8-020
A14: MSG-0003 | B14: You do not have permission to perform this action. | C14: Cố tình sửa URL xem học sinh của phụ huynh khác (IDOR Protection) | D14: TC-R8-013
A17: QUY CHUẨN ĐỊNH DẠNG DỮ LIỆU SINGAPORE (TABLE 119 CONTRACTS)
A18: Trường Dữ Liệu | B18: Kiểu & Giới Hạn | C18: Bắt Buộc | D18: Cho Phép Sửa | E18: Biểu Thức Regex / Thuật Toán Kiểm Tra | F18: Ghi Chú Nghiệp Vụ
A19: Full Name | B19: NVARCHAR(150) | C19: Không | D19: Không (Read-only) | E19: Trích xuất trực tiếp từ SingPass | F19: Bất biến; không có ô input
A20: NRIC | B20: VARCHAR(9) | C20: Không | D20: Không (Read-only) | E20: ^[STFG]\d{7}[A-Z]$ | F20: Che mặc định dạng S****321B; nút Show/Hide
A21: Residential Address | B21: Block, Street, Unit, Postal, Country | C21: Không | D21: Không (Read-only) | E21: Trích xuất từ SingPass theo Quyết định D-20 | F21: Bất biến; không có ô input
A22: Mobile Number | B22: VARCHAR(20), đúng 8 chữ số | C22: Có | D22: Có | E22: ^[689]\d{7}$ | F22: Bắt đầu 6, 8, 9; cho phép space nhưng phải trim
A23: Email Address | B23: NVARCHAR(150), tối đa 150 ký tự | C23: Có | D23: Có | E23: ^[a-zA-Z0-9._%+-]+@[a-zA-Z0-9.-]+\.[a-zA-Z]{2,}$ | F23: Chuẩn RFC 5322; tối đa 150 ký tự
A24: Mailing Street | B24: NVARCHAR(100), tối đa 100 ký tự | C24: Có | D24: Có | E24: 1 <= length <= 100 | F24: Bắt buộc; hỗ trợ ký tự địa chỉ Singapore
A25: Mailing Postal Code | B25: VARCHAR(10), đúng 6 chữ số | C25: Có | D25: Có | E25: ^\d{6}$ | F25: Đúng 6 số bưu chính; chấp nhận số 0 đầu
A26: Mailing Country | B26: NVARCHAR(100), tối đa 100 ký tự | C26: Có | D26: Có | E26: 1 <= length <= 100 | F26: Mặc định SINGAPORE
A27: Mailing Block | B27: NVARCHAR(20), tối đa 20 ký tự | C27: Không | D27: Có | E27: 0 <= length <= 20 | F27: Tùy chọn (Optional)
A28: Mailing Unit | B28: NVARCHAR(20), tối đa 20 ký tự | C28: Không | D28: Có | E28: 0 <= length <= 20 | F28: Tùy chọn (Optional)
